Traceback (most recent call last):
  File "/work/07797/kdm3465/maverick2/final_venv/lib/python3.7/site-packages/pandas/core/internals/construction.py", line 564, in _list_to_arrays
    columns = _validate_or_indexify_columns(content, columns)
  File "/work/07797/kdm3465/maverick2/final_venv/lib/python3.7/site-packages/pandas/core/internals/construction.py", line 689, in _validate_or_indexify_columns
    f"{len(columns)} columns passed, passed data had "
AssertionError: 3 columns passed, passed data had 19 columns

The above exception was the direct cause of the following exception:

Traceback (most recent call last):
  File "/work/07797/kdm3465/maverick2/final/M3.py", line 189, in <module>
    prune_info_df = pd.DataFrame(columns=('Prune Fraction', 'Test Accuracy', 'Train Accuracy'), data=(prune_frac_hist, test_acc_hist, train_acc_hist))
  File "/work/07797/kdm3465/maverick2/final_venv/lib/python3.7/site-packages/pandas/core/frame.py", line 509, in __init__
    arrays, columns = to_arrays(data, columns, dtype=dtype)
  File "/work/07797/kdm3465/maverick2/final_venv/lib/python3.7/site-packages/pandas/core/internals/construction.py", line 524, in to_arrays
    return _list_to_arrays(data, columns, coerce_float=coerce_float, dtype=dtype)
  File "/work/07797/kdm3465/maverick2/final_venv/lib/python3.7/site-packages/pandas/core/internals/construction.py", line 567, in _list_to_arrays
    raise ValueError(e) from e
ValueError: 3 columns passed, passed data had 19 columns
